Traceback (most recent call last):
  File "<string>", line 1, in <module>
ModuleNotFoundError: No module named 'torch'
2025-05-06 09:13:41.231832: I tensorflow/core/util/port.cc:153] oneDNN custom operations are on. You may see slightly different numerical results due to floating-point round-off errors from different computation orders. To turn them off, set the environment variable `TF_ENABLE_ONEDNN_OPTS=0`.
2025-05-06 09:13:43.100303: E external/local_xla/xla/stream_executor/cuda/cuda_fft.cc:467] Unable to register cuFFT factory: Attempting to register factory for plugin cuFFT when one has already been registered
WARNING: All log messages before absl::InitializeLog() is called are written to STDERR
E0000 00:00:1746540823.355402 2582667 cuda_dnn.cc:8579] Unable to register cuDNN factory: Attempting to register factory for plugin cuDNN when one has already been registered
E0000 00:00:1746540823.408282 2582667 cuda_blas.cc:1407] Unable to register cuBLAS factory: Attempting to register factory for plugin cuBLAS when one has already been registered
W0000 00:00:1746540824.252877 2582667 computation_placer.cc:177] computation placer already registered. Please check linkage and avoid linking the same target more than once.
W0000 00:00:1746540824.252925 2582667 computation_placer.cc:177] computation placer already registered. Please check linkage and avoid linking the same target more than once.
W0000 00:00:1746540824.252929 2582667 computation_placer.cc:177] computation placer already registered. Please check linkage and avoid linking the same target more than once.
W0000 00:00:1746540824.252932 2582667 computation_placer.cc:177] computation placer already registered. Please check linkage and avoid linking the same target more than once.
2025-05-06 09:13:44.257959: I tensorflow/core/platform/cpu_feature_guard.cc:210] This TensorFlow binary is optimized to use available CPU instructions in performance-critical operations.
To enable the following instructions: AVX2 AVX512F AVX512_VNNI AVX512_BF16 AVX512_FP16 AVX_VNNI AMX_TILE AMX_INT8 AMX_BF16 FMA, in other operations, rebuild TensorFlow with the appropriate compiler flags.
/home/jci0365/miniconda3/envs/vae/lib/python3.9/site-packages/requests/__init__.py:86: RequestsDependencyWarning: Unable to find acceptable character detection dependency (chardet or charset_normalizer).
  warnings.warn(
Traceback (most recent call last):
  File "/home/jci0365/miniconda3/envs/vae/lib/python3.9/site-packages/huggingface_hub/utils/_http.py", line 409, in hf_raise_for_status
    response.raise_for_status()
  File "/home/jci0365/miniconda3/envs/vae/lib/python3.9/site-packages/requests/models.py", line 1024, in raise_for_status
    raise HTTPError(http_error_msg, response=self)
requests.exceptions.HTTPError: 401 Client Error: Unauthorized for url: https://huggingface.co/bert-base_uncased/resolve/main/tokenizer_config.json

The above exception was the direct cause of the following exception:

Traceback (most recent call last):
  File "/home/jci0365/miniconda3/envs/vae/lib/python3.9/site-packages/transformers/utils/hub.py", line 424, in cached_files
    hf_hub_download(
  File "/home/jci0365/miniconda3/envs/vae/lib/python3.9/site-packages/huggingface_hub/utils/_validators.py", line 114, in _inner_fn
    return fn(*args, **kwargs)
  File "/home/jci0365/miniconda3/envs/vae/lib/python3.9/site-packages/huggingface_hub/file_download.py", line 961, in hf_hub_download
    return _hf_hub_download_to_cache_dir(
  File "/home/jci0365/miniconda3/envs/vae/lib/python3.9/site-packages/huggingface_hub/file_download.py", line 1068, in _hf_hub_download_to_cache_dir
    _raise_on_head_call_error(head_call_error, force_download, local_files_only)
  File "/home/jci0365/miniconda3/envs/vae/lib/python3.9/site-packages/huggingface_hub/file_download.py", line 1596, in _raise_on_head_call_error
    raise head_call_error
  File "/home/jci0365/miniconda3/envs/vae/lib/python3.9/site-packages/huggingface_hub/file_download.py", line 1484, in _get_metadata_or_catch_error
    metadata = get_hf_file_metadata(
  File "/home/jci0365/miniconda3/envs/vae/lib/python3.9/site-packages/huggingface_hub/utils/_validators.py", line 114, in _inner_fn
    return fn(*args, **kwargs)
  File "/home/jci0365/miniconda3/envs/vae/lib/python3.9/site-packages/huggingface_hub/file_download.py", line 1401, in get_hf_file_metadata
    r = _request_wrapper(
  File "/home/jci0365/miniconda3/envs/vae/lib/python3.9/site-packages/huggingface_hub/file_download.py", line 285, in _request_wrapper
    response = _request_wrapper(
  File "/home/jci0365/miniconda3/envs/vae/lib/python3.9/site-packages/huggingface_hub/file_download.py", line 309, in _request_wrapper
    hf_raise_for_status(response)
  File "/home/jci0365/miniconda3/envs/vae/lib/python3.9/site-packages/huggingface_hub/utils/_http.py", line 459, in hf_raise_for_status
    raise _format(RepositoryNotFoundError, message, response) from e
huggingface_hub.errors.RepositoryNotFoundError: 401 Client Error. (Request ID: Root=1-681a1953-6496a423006324cf78733efc;0df61015-a33c-4ee8-a476-7c0f94380de6)

Repository Not Found for url: https://huggingface.co/bert-base_uncased/resolve/main/tokenizer_config.json.
Please make sure you specified the correct `repo_id` and `repo_type`.
If you are trying to access a private or gated repo, make sure you are authenticated. For more details, see https://huggingface.co/docs/huggingface_hub/authentication
Invalid username or password.

The above exception was the direct cause of the following exception:

Traceback (most recent call last):
  File "/home/jci0365/Text-to-Sketch-Using-VAE/training/train.py", line 9, in <module>
    from preprocessing import SketchDataset
  File "/gpfs/home/jci0365/Text-to-Sketch-Using-VAE/training/preprocessing.py", line 83, in <module>
    train_dataset = SketchDataset()
  File "/gpfs/home/jci0365/Text-to-Sketch-Using-VAE/training/preprocessing.py", line 20, in __init__
    self.tokenizer = BertTokenizer.from_pretrained("bert-base_uncased")
  File "/home/jci0365/miniconda3/envs/vae/lib/python3.9/site-packages/transformers/tokenization_utils_base.py", line 1988, in from_pretrained
    resolved_config_file = cached_file(
  File "/home/jci0365/miniconda3/envs/vae/lib/python3.9/site-packages/transformers/utils/hub.py", line 266, in cached_file
    file = cached_files(path_or_repo_id=path_or_repo_id, filenames=[filename], **kwargs)
  File "/home/jci0365/miniconda3/envs/vae/lib/python3.9/site-packages/transformers/utils/hub.py", line 456, in cached_files
    raise OSError(
OSError: bert-base_uncased is not a local folder and is not a valid model identifier listed on 'https://huggingface.co/models'
If this is a private repository, make sure to pass a token having permission to this repo either by logging in with `huggingface-cli login` or by passing `token=<your_token>`
